<?xml version="1.0" encoding="utf-8"?>
<!-- =================================================================================== -->
<!-- |    This document was autogenerated by xacro from navbot.xacro                   | -->
<!-- |    EDITING THIS FILE BY HAND IS NOT RECOMMENDED                                 | -->
<!-- =================================================================================== -->
<robot name="navbot">
  <material name="silver">
    <color rgba="0.700 0.700 0.700 1.000"/>
  </material>

  <link name="base_link">
    <inertial>
      <origin rpy="0 0 0" xyz="0.0003147036812539107 8.654508451147519e-05 0.10819103947899564"/>
      <mass value="12.261671363009004"/>
      <inertia ixx="0.081478" ixy="-0.0" ixz="9.1e-05" iyy="0.132969" iyz="2.5e-05" izz="0.169987"/>
    </inertial>
    <visual>
      <origin rpy="0 0 0" xyz="0 0 0"/>
      <geometry>
        <mesh filename="package://navbot_description/meshes/base_link.stl" scale="0.001 0.001 0.001"/>
      </geometry>
      <material name="silver"/>
    </visual>
    <collision>
      <origin rpy="0 0 0" xyz="0 0 0"/>
      <geometry>
        <mesh filename="package://navbot_description/meshes/base_link.stl" scale="0.001 0.001 0.001"/>
      </geometry>
    </collision>
  </link>
  
  <link name="back_right_1">
    <inertial>
      <origin rpy="0 0 0" xyz="-4.597357573521421e-07 -0.02052480177758853 3.5268927792847515e-07"/>
      <mass value="4.878358553104739"/>
      <inertia ixx="0.006717" ixy="-0.0" ixz="-0.0" iyy="0.010579" iyz="-0.0" izz="0.006717"/>
    </inertial>
    <visual>
      <origin rpy="0 0 0" xyz="0.099572 0.149882 -0.060076"/>
      <geometry>
        <mesh filename="package://navbot_description/meshes/back_right_1.stl" scale="0.001 0.001 0.001"/>
      </geometry>
      <material name="silver"/>
    </visual>
    <collision>
      <origin rpy="0 0 0" xyz="0.099572 0.149882 -0.060076"/>
      <geometry>
        <mesh filename="package://navbot_description/meshes/back_right_1.stl" scale="0.001 0.001 0.001"/>
      </geometry>
    </collision>
  </link>
  <link name="front_right_1">
    <inertial>
      <origin rpy="0 0 0" xyz="-4.5917696378516837e-07 -0.02052480177758842 3.532853243698453e-07"/>
      <mass value="4.878358553104739"/>
      <inertia ixx="0.006717" ixy="-0.0" ixz="-0.0" iyy="0.010579" iyz="0.0" izz="0.006717"/>
    </inertial>
    <visual>
      <origin rpy="0 0 0" xyz="-0.100428 0.149882 -0.060076"/>
      <geometry>
        <mesh filename="package://navbot_description/meshes/front_right_1.stl" scale="0.001 0.001 0.001"/>
      </geometry>
      <material name="silver"/>
    </visual>
    <collision>
      <origin rpy="0 0 0" xyz="-0.100428 0.149882 -0.060076"/>
      <geometry>
        <mesh filename="package://navbot_description/meshes/front_right_1.stl" scale="0.001 0.001 0.001"/>
      </geometry>
    </collision>
  </link>
  <link name="back_left_1">
    <inertial>
      <origin rpy="0 0 0" xyz="-4.591769638545573e-07 0.02052395350161601 3.5268927771336944e-07"/>
      <mass value="4.878358553104739"/>
      <inertia ixx="0.006717" ixy="0.0" ixz="0.0" iyy="0.010579" iyz="0.0" izz="0.006717"/>
    </inertial>
    <visual>
      <origin rpy="0 0 0" xyz="0.099572 -0.150118 -0.060076"/>
      <geometry>
        <mesh filename="package://navbot_description/meshes/back_left_1.stl" scale="0.001 0.001 0.001"/>
      </geometry>
      <material name="silver"/>
    </visual>
    <collision>
      <origin rpy="0 0 0" xyz="0.099572 -0.150118 -0.060076"/>
      <geometry>
        <mesh filename="package://navbot_description/meshes/back_left_1.stl" scale="0.001 0.001 0.001"/>
      </geometry>
    </collision>
  </link>
  <link name="front_left_1">
    <inertial>
      <origin rpy="0 0 0" xyz="-4.5917696392394625e-07 0.020523953501616038 3.5328532416167846e-07"/>
      <mass value="4.878358553104739"/>
      <inertia ixx="0.006717" ixy="0.0" ixz="0.0" iyy="0.010579" iyz="0.0" izz="0.006717"/>
    </inertial>
    <visual>
      <origin rpy="0 0 0" xyz="-0.100428 -0.150118 -0.060076"/>
      <geometry>
        <mesh filename="package://navbot_description/meshes/front_left_1.stl" scale="0.001 0.001 0.001"/>
      </geometry>
      <material name="silver"/>
    </visual>
    <collision>
      <origin rpy="0 0 0" xyz="-0.100428 -0.150118 -0.060076"/>
      <geometry>
        <mesh filename="package://navbot_description/meshes/front_left_1.stl" scale="0.001 0.001 0.001"/>
      </geometry>
    </collision>
  </link>
  <link name="laser1">
    <inertial>
      <origin rpy="0 0 0" xyz="0.0002638330985168125 -0.0007615524008374664 0.020624066504128902"/>
      <mass value="1.6657432797148926"/>
      <inertia ixx="0.001074" ixy="0.0" ixz="-4e-06" iyy="0.001074" iyz="1.2e-05" izz="0.001371"/>
    </inertial>
    <visual>
      <origin rpy="0 0 0" xyz="0.065 0.0 -0.22"/>
      <geometry>
        <mesh filename="package://navbot_description/meshes/laser_link_v1_1.stl" scale="0.001 0.001 0.001"/>
      </geometry>
      <material name="silver"/>
    </visual>
    <collision>
      <origin rpy="0 0 0" xyz="0.065 0.0 -0.22"/>
      <geometry>
        <mesh filename="package://navbot_description/meshes/laser_link_v1_1.stl" scale="0.001 0.001 0.001"/>
      </geometry>
    </collision>
  </link>

  <link name="laser2">
    <inertial>
      <origin rpy="0 0 0" xyz="0.0002638330985168125 -0.0007615524008374664 0.020624066504128902"/>
      <mass value="1.6657432797148926"/>
      <inertia ixx="0.001074" ixy="0.0" ixz="-4e-06" iyy="0.001074" iyz="1.2e-05" izz="0.001371"/>
    </inertial>
    <visual>
      <origin rpy="220 12.57 110" xyz="0.135 -0.0085 -0.1"/>
      <geometry>
        <mesh filename="package://navbot_description/meshes/laser_link_1.stl" scale="0.001 0.001 0.001"/>
      </geometry>
      <material name="silver"/>
    </visual>
    <collision>
      <origin rpy="220 12.57 110" xyz="0.135 -0.0085 -0.1"/>
      <geometry>
        <mesh filename="package://navbot_description/meshes/laser_link_1.stl" scale="0.001 0.001 0.001"/>
      </geometry>
    </collision>
  </link>


  <!--link name="camera_link_v1_1">
    <inertial>
      <origin rpy="0 0 0" xyz="-0.010094496944980769 1.27997814036277e-05 -0.14999905153125456"/>
      <mass value="0.18735731616487916"/>
      <inertia ixx="0.000194" ixy="-0.0" ixz="-0.0" iyy="4e-05" iyz="0.0" izz="0.000155"/>
    </inertial>
    <visual>
      <origin rpy="0 0 0" xyz="-0.150428 -0.000118 -0.280076"/>
      <geometry>
        <mesh filename="package://navbot_description/meshes/camera_link_v1_1.stl" scale="0.001 0.001 0.001"/>
      </geometry>
      <material name="silver"/>
    </visual>
    <collision>
      <origin rpy="0 0 0" xyz="-0.150428 -0.000118 -0.280076"/>
      <geometry>
        <mesh filename="package://navbot_description/meshes/camera_link_v1_1.stl" scale="0.001 0.001 0.001"/>
      </geometry>
    </collision>
  </link-->

  <joint name="Rev1" type="continuous">
    <origin rpy="0 0 0" xyz="-0.099572 -0.149882 0.060076"/>
    <parent link="base_link"/>
    <child link="back_right_1"/>
    <axis xyz="0.0 1.0 -0.0"/>
  </joint>

  <joint name="Rev3" type="continuous">
    <origin rpy="0 0 0" xyz="0.100428 -0.149882 0.060076"/>
    <parent link="base_link"/>
    <child link="front_right_1"/>
    <axis xyz="0.0 1.0 -0.0"/>
  </joint>
  <joint name="Rev4" type="continuous">
    <origin rpy="0 0 0" xyz="-0.099572 0.150118 0.060076"/>
    <parent link="base_link"/>
    <child link="back_left_1"/>
    <axis xyz="-0.0 1.0 0.0"/>
  </joint>
  <joint name="Rev5" type="continuous">
    <origin rpy="0 0 0" xyz="0.100428 0.150118 0.060076"/>
    <parent link="base_link"/>
    <child link="front_left_1"/>
    <axis xyz="-0.0 0.0 1.0"/>
  </joint>

  <joint name="Rigid8" type="fixed">
    <origin rpy="0 0 0" xyz="-0.03 0.0 0.3"/>
    <parent link="base_link"/>
    <child link="laser1"/>
  </joint>

  <joint name="Rigid10" type="fixed">
    <origin rpy="110 11 0" xyz="-0.005 0.001 0.18"/>
    <parent link="base_link"/>
    <child link="laser2"/>
  </joint>
  <!--joint name="Rigid9" type="fixed">
    <origin rpy="0 0 0" xyz="0.150428 0.000118 0.280076"/>
    <parent link="base_link"/>
    <child link="camera_link_v1_1"/>
  </joint-->

    <transmission name="Rev1_tran">
    <type>transmission_interface/SimpleTransmission</type>

    <joint name="Rev1">
      <hardwareInterface>hardware_interface/EffortJointInterface</hardwareInterface>
    </joint>

    <actuator name="Rev1_actr">
      <hardwareInterface>hardware_interface/EffortJointInterface</hardwareInterface>
      <mechanicalReduction>1</mechanicalReduction>
    </actuator>
  </transmission>

  <transmission name="Rev3_tran">
    <type>transmission_interface/SimpleTransmission</type>
    <joint name="Rev3">
      <hardwareInterface>hardware_interface/EffortJointInterface</hardwareInterface>
    </joint>
    <actuator name="Rev3_actr">
      <hardwareInterface>hardware_interface/EffortJointInterface</hardwareInterface>
      <mechanicalReduction>1</mechanicalReduction>
    </actuator>
  </transmission>
  <transmission name="Rev4_tran">
    <type>transmission_interface/SimpleTransmission</type>
    <joint name="Rev4">
      <hardwareInterface>hardware_interface/EffortJointInterface</hardwareInterface>
    </joint>
    <actuator name="Rev4_actr">
      <hardwareInterface>hardware_interface/EffortJointInterface</hardwareInterface>
      <mechanicalReduction>1</mechanicalReduction>
    </actuator>
  </transmission>
  <transmission name="Rev5_tran">
    <type>transmission_interface/SimpleTransmission</type>
    <joint name="Rev5">
      <hardwareInterface>hardware_interface/EffortJointInterface</hardwareInterface>
    </joint>
    <actuator name="Rev5_actr">
      <hardwareInterface>hardware_interface/EffortJointInterface</hardwareInterface>
      <mechanicalReduction>1</mechanicalReduction>
    </actuator>
  </transmission>

  <gazebo>
    <plugin filename="libgazebo_ros_control.so" name="control"/>
  </gazebo>

  <gazebo reference="base_link">
    <material>Gazebo/Silver</material>
    <mu1>0.2</mu1>
    <mu2>0.2</mu2>
    <selfCollide>true</selfCollide>
    <gravity>true</gravity>
  </gazebo>
  
  <gazebo reference="back_right_1">
    <material>Gazebo/Silver</material>
    <mu1>0.2</mu1>
    <mu2>0.2</mu2>
    <selfCollide>true</selfCollide>
  </gazebo>
  <gazebo reference="front_right_1">
    <material>Gazebo/Silver</material>
    <mu1>0.2</mu1>
    <mu2>0.2</mu2>
    <selfCollide>true</selfCollide>
  </gazebo>
  <gazebo reference="back_left_1">
    <material>Gazebo/Silver</material>
    <mu1>0.2</mu1>
    <mu2>0.2</mu2>
    <selfCollide>true</selfCollide>
  </gazebo>
  <gazebo reference="front_left_1">
    <material>Gazebo/Silver</material>
    <mu1>0.2</mu1>
    <mu2>0.2</mu2>
    <selfCollide>true</selfCollide>
  </gazebo>
  <gazebo reference="laser1">
    <material>Gazebo/Silver</material>
    <mu1>0.2</mu1>
    <mu2>0.2</mu2>
    <selfCollide>true</selfCollide>
  </gazebo>
  <gazebo reference="laser2">
    <material>Gazebo/Silver</material>
    <mu1>0.2</mu1>
    <mu2>0.2</mu2>
    <selfCollide>true</selfCollide>
  </gazebo>
  <!--gazebo reference="camera_link_v1_1">
    <material>Gazebo/Silver</material>
    <mu1>0.2</mu1>
    <mu2>0.2</mu2>
    <selfCollide>true</selfCollide>
  </gazebo-->
  <!--gazebo>
    <plugin filename="libgazebo_ros_skid_steer_drive.so" name="skid_steer_drive_controller">
      <updateRate>100.0</updateRate>
      <robotNamespace>/</robotNamespace>
      <leftFrontJoint>Rev5</leftFrontJoint>
      <rightFrontJoint>Rev3</rightFrontJoint>
      <leftRearJoint>Rev4</leftRearJoint>
      <rightRearJoint>Rev1</rightRearJoint>
      <wheelSeparation>0.4</wheelSeparation>
      <wheelDiameter>0.125</wheelDiameter>
      <robotBaseFrame>base_footprint</robotBaseFrame>
      <torque>20</torque>
      <topicName>cmd_vel</topicName>
      <broadcastTF>true</broadcastTF>
    </plugin>
  </gazebo-->

   <gazebo>
    <plugin filename="libgazebo_ros_diff_drive.so" name="differential_drive_controller_front">
      <rosDebugLevel>Debug</rosDebugLevel>
      <publishWheelTF>True</publishWheelTF>
      <publishTf>1</publishTf>
      <publishWheelJointState>true</publishWheelJointState>
      <alwaysOn>true</alwaysOn>
      <publishOdomTF>true</publishOdomTF>
      <robotBaseFrame>base_footprint</robotBaseFrame>
      <publishWheelTF>false</publishWheelTF>
      <updateRate>100.0</updateRate>
      <leftJoint>Rev1</leftJoint>
      <rightJoint>Rev3</rightJoint>
      <wheelSeparation>0.3</wheelSeparation>
      <wheelDiameter>0.08</wheelDiameter>
      <broadcastTF>1</broadcastTF>
      <wheelTorque>30</wheelTorque>
      <wheelAcceleration>1.8</wheelAcceleration>
      <commandTopic>cmd_vel</commandTopic>
      <odometryFrame>odom</odometryFrame>
      <odometryTopic>odom</odometryTopic>
      <robotBaseFrame>base_footprint</robotBaseFrame>
    </plugin>
  </gazebo> 

 !-- hokuyo --&gt;

 <gazebo reference="laser1">
    <sensor name="laser1" type="ray">
      <pose>0 0 0 0 0 0</pose>
      <visualize>true</visualize>
      <update_rate>40</update_rate>
      <ray>
        <scan>
          <horizontal>
            <samples>720</samples>
            <resolution>1</resolution>
            <min_angle>-1.570796</min_angle>
            <max_angle>1.570796</max_angle>
          </horizontal>
        </scan>
        <range>
          <min>0.10</min>
          <max>30.0</max>
          <resolution>0.01</resolution>
        </range>
        <noise>
          <type>gaussian</type>
          
          <mean>0.0</mean>
          <stddev>0.01</stddev>
        </noise>
      </ray>
      <plugin filename="libgazebo_ros_laser.so" name="gazebo_ros_head_hokuyo_controller">
        <topicName>horizontal_scan</topicName>
        <frameName>laser1</frameName>
      </plugin>
    </sensor>
  </gazebo>
  
  

    <gazebo reference="laser2">
    <sensor name="laser2" type="ray">
      <pose>0 0 0.09 1.5708 0 -1.5708</pose>
      <visualize>true</visualize>
      <update_rate>40</update_rate>
      <ray>
        <scan>
          <horizontal>
            <samples>720</samples>
            <resolution>1</resolution>
            <min_angle>-1.570796</min_angle>
            <max_angle>1.570796</max_angle>
          </horizontal>
        </scan>
        <range>
          <min>0.10</min>
          <max>30.0</max>
          <resolution>0.01</resolution>
        </range>
        <noise>
          <type>gaussian</type>
          
          <mean>0.0</mean>
          <stddev>0.01</stddev>
        </noise>
      </ray>
      <plugin filename="libgazebo_ros_laser.so" name="gazebo_ros_head_hokuyo_controller">
        <topicName>vertical_scan</topicName>
        <frameName>laser2</frameName>
      </plugin>
    </sensor>
  </gazebo>
 

<!--gazebo reference="camera_link_v1_1">
    <sensor type="depth" name="realsense_R200">
      <always_on>true</always_on>
      
      <camera>
          <horizontal_fov>1.3439</horizontal_fov>
          <image>
              <width>1920</width>
              <height>1080</height>
              <format>R8G8B8</format>
          </image>
          <depth_camera></depth_camera>
          <clip>
              <near>0.03</near>
              <far>100</far>
          </clip>
      </camera>
      <plugin name="camera_controller" filename="libgazebo_ros_openni_kinect.so">
        <baseline>0.2</baseline>
        <alwaysOn>true</alwaysOn>
        <updateRate>30.0</updateRate>
        <cameraName>camera</cameraName>
        <frameName>camera_link_v1_1</frameName>
        <imageTopicName>rgb/image_raw</imageTopicName>
        <depthImageTopicName>depth/image_raw</depthImageTopicName>
        <pointCloudTopicName>depth/points</pointCloudTopicName>
        <cameraInfoTopicName>rgb/camera_info</cameraInfoTopicName>
        <depthImageCameraInfoTopicName>depth/camera_info</depthImageCameraInfoTopicName>
        <pointCloudCutoff>0.4</pointCloudCutoff>
            <hackBaseline>0.07</hackBaseline>
            <distortionK1>0.0</distortionK1>
            <distortionK2>0.0</distortionK2>
            <distortionK3>0.0</distortionK3>
            <distortionT1>0.0</distortionT1>
            <distortionT2>0.0</distortionT2>
        <CxPrime>0.0</CxPrime>
        <Cx>0.0</Cx>
        <Cy>0.0</Cy>
        <focalLength>0</focalLength>
        <hackBaseline>0</hackBaseline>
      </plugin>
    </sensor>
  </gazebo!-->
</robot>
